<?xml version="1.0"?>
<!-- Generated from /doc/ares/flatsim/examples/machines/husky.json -->
<robot name="clearpath_husky">

  <link name="base_link">
    <visual>
      <origin xyz="0 0 0.495" rpy="0 0 0"/>
      <geometry>
        <box size="0.67 0.67 0.99"/>
      </geometry>
      <material name="husky_color">
        <color rgba="0.502 0.0 1.0 1.0"/>
      </material>
    </visual>
    <collision>
      <origin xyz="0 0 0.495" rpy="0 0 0"/>
      <geometry>
        <box size="0.67 0.67 0.99"/>
      </geometry>
    </collision>
  </link>

  <!-- Wheels (radius=0.125, length=0.15). base_link is on ground plane -->

  <link name="front_right_wheel">
    <visual>
      <origin xyz="0 0 0" rpy="0 1.57079632679 0"/>
      <geometry>
        <cylinder radius="0.125" length="0.15"/>
      </geometry>
    </visual>
    <collision>
      <origin xyz="0 0 0" rpy="0 1.57079632679 0"/>
      <geometry>
        <cylinder radius="0.125" length="0.15"/>
      </geometry>
    </collision>
  </link>
  <joint name="front_right_wheel_joint" type="continuous">
    <parent link="base_link"/>
    <child link="front_right_wheel"/>
    <origin xyz="0.335 0.3 0.125" rpy="0 0 0"/>
    <axis xyz="0 1 0"/>
  </joint>

  <link name="front_left_wheel">
    <visual>
      <origin xyz="0 0 0" rpy="0 1.57079632679 0"/>
      <geometry>
        <cylinder radius="0.125" length="0.15"/>
      </geometry>
    </visual>
    <collision>
      <origin xyz="0 0 0" rpy="0 1.57079632679 0"/>
      <geometry>
        <cylinder radius="0.125" length="0.15"/>
      </geometry>
    </collision>
  </link>
  <joint name="front_left_wheel_joint" type="continuous">
    <parent link="base_link"/>
    <child link="front_left_wheel"/>
    <origin xyz="-0.335 0.3 0.125" rpy="0 0 0"/>
    <axis xyz="0 1 0"/>
  </joint>

  <link name="rear_right_wheel">
    <visual>
      <origin xyz="0 0 0" rpy="0 1.57079632679 0"/>
      <geometry>
        <cylinder radius="0.125" length="0.15"/>
      </geometry>
    </visual>
    <collision>
      <origin xyz="0 0 0" rpy="0 1.57079632679 0"/>
      <geometry>
        <cylinder radius="0.125" length="0.15"/>
      </geometry>
    </collision>
  </link>
  <joint name="rear_right_wheel_joint" type="continuous">
    <parent link="base_link"/>
    <child link="rear_right_wheel"/>
    <origin xyz="0.335 -0.3 0.125" rpy="0 0 0"/>
    <axis xyz="0 1 0"/>
  </joint>

  <link name="rear_left_wheel">
    <visual>
      <origin xyz="0 0 0" rpy="0 1.57079632679 0"/>
      <geometry>
        <cylinder radius="0.125" length="0.15"/>
      </geometry>
    </visual>
    <collision>
      <origin xyz="0 0 0" rpy="0 1.57079632679 0"/>
      <geometry>
        <cylinder radius="0.125" length="0.15"/>
      </geometry>
    </collision>
  </link>
  <joint name="rear_left_wheel_joint" type="continuous">
    <parent link="base_link"/>
    <child link="rear_left_wheel"/>
    <origin xyz="-0.335 -0.3 0.125" rpy="0 0 0"/>
    <axis xyz="0 1 0"/>
  </joint>

</robot>
