<?xml version="1.0"?>
<!-- Generated from /doc/ares/flatsim/examples/machines/trailer.json -->
<robot name="grain_trailer">

  <link name="base_link">
    <visual>
      <origin xyz="0 0 1.3" rpy="0 0 0"/>
      <geometry>
        <box size="1.8 5.08 2.6"/>
      </geometry>
      <material name="trailer_color">
        <color rgba="1.0 0.588 0.0 1.0"/>
      </material>
    </visual>
    <collision>
      <origin xyz="0 0 1.3" rpy="0 0 0"/>
      <geometry>
        <box size="1.8 5.08 2.6"/>
      </geometry>
    </collision>
  </link>

  <!-- Wheels (radius=0.39, length=0.396). base_link is on ground plane -->
  <link name="rear_right_wheel">
    <visual>
      <origin xyz="0 0 0" rpy="0 1.57079632679 0"/>
      <geometry>
        <cylinder radius="0.39" length="0.396"/>
      </geometry>
    </visual>
    <collision>
      <origin xyz="0 0 0" rpy="0 1.57079632679 0"/>
      <geometry>
        <cylinder radius="0.39" length="0.396"/>
      </geometry>
    </collision>
  </link>
  <joint name="rear_right_wheel_joint" type="continuous">
    <parent link="base_link"/>
    <child link="rear_right_wheel"/>
    <origin xyz="0.9 -0.78 0.39" rpy="0 0 0"/>
    <axis xyz="0 1 0"/>
  </joint>

  <link name="rear_left_wheel">
    <visual>
      <origin xyz="0 0 0" rpy="0 1.57079632679 0"/>
      <geometry>
        <cylinder radius="0.39" length="0.396"/>
      </geometry>
    </visual>
    <collision>
      <origin xyz="0 0 0" rpy="0 1.57079632679 0"/>
      <geometry>
        <cylinder radius="0.39" length="0.396"/>
      </geometry>
    </collision>
  </link>
  <joint name="rear_left_wheel_joint" type="continuous">
    <parent link="base_link"/>
    <child link="rear_left_wheel"/>
    <origin xyz="-0.9 -0.78 0.39" rpy="0 0 0"/>
    <axis xyz="0 1 0"/>
  </joint>

  <!-- Karosseries -->
  <link name="towing_pole">
    <visual>
      <origin xyz="0 0 0" rpy="0 0 0"/>
      <geometry>
        <box size="0.18 1.04 0.2"/>
      </geometry>
    </visual>
  </link>
  <joint name="towing_pole_joint" type="fixed">
    <parent link="base_link"/>
    <child link="towing_pole"/>
    <origin xyz="0 1.82 0" rpy="0 0 0"/>
  </joint>

  <link name="hitch_mount">
    <visual>
      <origin xyz="0 0 0" rpy="0 0 0"/>
      <geometry>
        <box size="0.24 0.28 0.2"/>
      </geometry>
    </visual>
  </link>
  <joint name="hitch_mount_joint" type="fixed">
    <parent link="base_link"/>
    <child link="hitch_mount"/>
    <origin xyz="0 -1.30 0" rpy="0 0 0"/>
  </joint>

  <!-- Hitches -->
  <link name="front_hitch">
    <visual>
      <origin xyz="0 0 0" rpy="0 0 0"/>
      <geometry>
        <box size="0.05 0.05 0.05"/>
      </geometry>
    </visual>
  </link>
  <joint name="front_hitch_joint" type="fixed">
    <parent link="base_link"/>
    <child link="front_hitch"/>
    <origin xyz="0 2.54 0" rpy="0 0 0"/>
  </joint>

  <link name="rear_hitch">
    <visual>
      <origin xyz="0 0 0" rpy="0 0 0"/>
      <geometry>
        <box size="0.05 0.05 0.05"/>
      </geometry>
    </visual>
  </link>
  <joint name="rear_hitch_joint" type="fixed">
    <parent link="base_link"/>
    <child link="rear_hitch"/>
    <origin xyz="0 -1.30 0" rpy="0 0 0"/>
  </joint>

  <!-- Tank as a fixed link -->
  <link name="storage_bin">
    <visual>
      <origin xyz="0 0 0" rpy="0 0 0"/>
      <geometry>
        <box size="1.62 2.34 0.8"/>
      </geometry>
    </visual>
  </link>
  <joint name="storage_bin_joint" type="fixed">
    <parent link="base_link"/>
    <child link="storage_bin"/>
    <origin xyz="0 0 0" rpy="0 0 0"/>
  </joint>

</robot>
